Workbook

Sheet newspaper_municipality_map
A1: newspaper_id | B1: newspaper_name | C1: publisher | D1: kommune_kode | E1: kommune_name | F1: region | G1: frequency | H1: type | I1: distribution | J1: est_circulation | K1: has_website | L1: source | M1: notes
A2: NP001 | B2: Ugeavisen Haderslev | C2: JFM | D2: 510 | E2: Haderslev | F2: Syddanmark | G2: weekly | H2: free | I2: local | J2: 0 | K2: yes | L2: ugeavisen.dk
A3: NP002 | B3: Ugeavisen Aabenraa | C3: JFM | D3: 580 | E3: Aabenraa | F3: Syddanmark | G3: weekly | H3: free | I3: local | J3: 30000 | K3: yes | L3: ugeavisen.dk + MediaVejviseren | M3: Også kaldet Aabenraa Ugeavis
A4: NP003 | B4: Ugeavisen Sønderborg | C4: JFM | D4: 540 | E4: Sønderborg | F4: Syddanmark | G4: weekly | H4: free | I4: local | J4: 0 | K4: yes | L4: ugeavisen.dk | M4: Også kaldet Sønderborg Ugeavis
A5: NP004 | B5: Ugeavisen Tønder | C5: JFM | D5: 550 | E5: Tønder | F5: Syddanmark | G5: weekly | H5: free | I5: local | J5: 0 | K5: yes | L5: ugeavisen.dk
A6: NP005 | B6: Ugeavisen Kolding | C6: JFM | D6: 621 | E6: Kolding | F6: Syddanmark | G6: weekly | H6: free | I6: local | J6: 41000 | K6: yes | L6: ugeavisen.dk + MediaVejviseren
A7: NP006 | B7: Ugeavisen Esbjerg | C7: JFM | D7: 561 | E7: Esbjerg | F7: Syddanmark | G7: weekly | H7: free | I7: local | J7: 0 | K7: yes | L7: ugeavisen.dk
A8: NP007 | B8: Ugeavisen Varde | C8: JFM | D8: 573 | E8: Varde | F8: Syddanmark | G8: weekly | H8: free | I8: local | J8: 0 | K8: yes | L8: ugeavisen.dk
A9: NP008 | B9: Ugeavisen Vejen | C9: JFM | D9: 575 | E9: Vejen | F9: Syddanmark | G9: weekly | H9: free | I9: local | J9: 0 | K9: yes | L9: ugeavisen.dk
A10: NP009 | B10: Ugeavisen Billund-Grindsted | C10: JFM | D10: 530 | E10: Billund | F10: Syddanmark | G10: weekly | H10: free | I10: local | J10: 0 | K10: yes | L10: ugeavisen.dk
A11: NP010 | B11: Ugeavisen Vejle | C11: JFM | D11: 630 | E11: Vejle | F11: Syddanmark | G11: weekly | H11: free | I11: local | J11: 0 | K11: yes | L11: ugeavisen.dk
A12: NP011 | B12: Ugeavisen Bramming | C12: JFM | D12: 561 | E12: Esbjerg | F12: Syddanmark | G12: weekly | H12: free | I12: local | J12: 0 | K12: yes | L12: ugeavisen.dk | M12: Dækker Bramming-området i Esbjerg Kommune
A13: NP012 | B13: Ugeavisen Ribe | C13: JFM | D13: 561 | E13: Esbjerg | F13: Syddanmark | G13: weekly | H13: free | I13: local | J13: 0 | K13: yes | L13: ugeavisen.dk | M13: Dækker Ribe-området i Esbjerg Kommune
A14: NP013 | B14: ElboBladet | C14: JFM | D14: 607 | E14: Fredericia | F14: Syddanmark | G14: weekly | H14: free | I14: local | J14: 38000 | K14: yes | L14: MediaVejviseren | M14: Dækker Fredericia og omegn
A15: NP014 | B15: Trekantens Folkeblad | C15: JFM | D15: 607 | E15: Fredericia | F15: Syddanmark | G15: weekly | H15: free | I15: regional | J15: 0 | K15: yes | L15: ugeavisen.dk | M15: Dækker Trekantområdet
A16: NP014 | B16: Trekantens Folkeblad | C16: JFM | D16: 621 | E16: Kolding | F16: Syddanmark | G16: weekly | H16: free | I16: regional | J16: 0 | K16: yes | L16: ugeavisen.dk | M16: Dækker Trekantområdet
A17: NP014 | B17: Trekantens Folkeblad | C17: JFM | D17: 630 | E17: Vejle | F17: Syddanmark | G17: weekly | H17: free | I17: regional | J17: 0 | K17: yes | L17: ugeavisen.dk | M17: Dækker Trekantområdet
A18: NP015 | B18: Jelling Ugeavis | C18: JFM | D18: 630 | E18: Vejle | F18: Syddanmark | G18: weekly | H18: free | I18: local | J18: 0 | K18: yes | L18: ugeavisen.dk | M18: Dækker Jelling-området i Vejle Kommune
A19: NP016 | B19: Horsens Posten | C19: JFM | D19: 615 | E19: Horsens | F19: Syddanmark | G19: weekly | H19: free | I19: local | J19: 0 | K19: yes | L19: ugeavisen.dk | M19: Ugeavis for Horsens
A20: NP020 | B20: Ugeavisen Odense | C20: JFM | D20: 461 | E20: Odense | F20: Syddanmark | G20: weekly | H20: free | I20: local | J20: 106000 | K20: yes | L20: MediaVejviseren
A21: NP021 | B21: Ugeavisen Svendborg | C21: JFM | D21: 479 | E21: Svendborg | F21: Syddanmark | G21: weekly | H21: free | I21: local | J21: 0 | K21: yes | L21: ugeavisen.dk
A22: NP022 | B22: Ugeavisen Faaborg | C22: JFM | D22: 430 | E22: Faaborg-Midtfyn | F22: Syddanmark | G22: weekly | H22: free | I22: local | J22: 0 | K22: yes | L22: ugeavisen.dk
A23: NP023 | B23: Kerteminde Ugeavis | C23: JFM | D23: 440 | E23: Kerteminde | F23: Syddanmark | G23: weekly | H23: free | I23: local | J23: 0 | K23: yes | L23: MediaVejviseren
A24: NP024 | B24: LokalAvisen Nyborg | C24: JFM | D24: 450 | E24: Nyborg | F24: Syddanmark | G24: weekly | H24: free | I24: local | J24: 0 | K24: yes | L24: MediaVejviseren
A25: NP025 | B25: LokalAvisen Assens | C25: JFM | D25: 420 | E25: Assens | F25: Syddanmark | G25: weekly | H25: free | I25: local | J25: 0 | K25: yes | L25: MediaVejviseren
A26: NP026 | B26: UgeAvisen Nordfyn | C26: JFM | D26: 480 | E26: Nordfyns | F26: Syddanmark | G26: weekly | H26: free | I26: local | J26: 0 | K26: yes | L26: MediaVejviseren | M26: Evt. også kaldet Område Avisen Nordfyn
A27: NP027 | B27: Midtfyns Posten | C27: JFM | D27: 430 | E27: Faaborg-Midtfyn | F27: Syddanmark | G27: weekly | H27: free | I27: local | J27: 0 | K27: yes | L27: MediaVejviseren | M27: Dækker Ringe/Midtfyn-området
A28: NP028 | B28: Ugeavisen Øboen | C28: JFM | D28: 482 | E28: Langeland | F28: Syddanmark | G28: weekly | H28: free | I28: local | J28: 0 | K28: yes | L28: MediaVejviseren | M28: Langeland
A29: NP029 | B29: Melfar Posten | C29: JFM | D29: 410 | E29: Middelfart | F29: Syddanmark | G29: weekly | H29: free | I29: local | J29: 0 | K29: yes | L29: MediaVejviseren
A30: NP040 | B30: Der Nordschleswiger | C30: BDN/Deutscher Presseverein | D30: 510 | E30: Haderslev | F30: Syddanmark | G30: digital | H30: free | I30: regional | J30: 0 | K30: yes | L30: Wikipedia + nordschleswig.dk | M30: Tysksproget; lokalredaktion i Haderslev
A31: NP040 | B31: Der Nordschleswiger | C31: BDN/Deutscher Presseverein | D31: 540 | E31: Sønderborg | F31: Syddanmark | G31: digital | H31: free | I31: regional | J31: 0 | K31: yes | L31: Wikipedia + nordschleswig.dk | M31: Lokalredaktion i Sønderborg
A32: NP040 | B32: Der Nordschleswiger | C32: BDN/Deutscher Presseverein | D32: 580 | E32: Aabenraa | F32: Syddanmark | G32: digital | H32: free | I32: regional | J32: 0 | K32: yes | L32: Wikipedia + nordschleswig.dk | M32: Hovedredaktion i Aabenraa
A33: NP040 | B33: Der Nordschleswiger | C33: BDN/Deutscher Presseverein | D33: 550 | E33: Tønder | F33: Syddanmark | G33: digital | H33: free | I33: regional | J33: 0 | K33: yes | L33: Wikipedia + nordschleswig.dk | M33: Lokalredaktion i Tønder
A34: NP041 | B34: Sydnyt.dk | C34: Uafhængig | D34: 510 | E34: Haderslev | F34: Syddanmark | G34: digital | H34: free | I34: regional | J34: 0 | K34: yes | L34: sydnyt.dk | M34: Gratis online nyhedsmedie for Sønderjylland
A35: NP041 | B35: Sydnyt.dk | C35: Uafhængig | D35: 540 | E35: Sønderborg | F35: Syddanmark | G35: digital | H35: free | I35: regional | J35: 0 | K35: yes | L35: sydnyt.dk
A36: NP041 | B36: Sydnyt.dk | C36: Uafhængig | D36: 580 | E36: Aabenraa | F36: Syddanmark | G36: digital | H36: free | I36: regional | J36: 0 | K36: yes | L36: sydnyt.dk
A37: NP041 | B37: Sydnyt.dk | C37: Uafhængig | D37: 550 | E37: Tønder | F37: Syddanmark | G37: digital | H37: free | I37: regional | J37: 0 | K37: yes | L37: sydnyt.dk
A38: NP042 | B38: AVISEN for Gråsten, Lundtoft og Sundeved | C38: Ukendt | D38: 540 | E38: Sønderborg | F38: Syddanmark | G38: weekly | H38: free | I38: local | J38: 10000 | K38: yes | L38: MediaVejviseren | M38: Hyperlokal; dækker dele af Sønderborg Kommune
A39: NP050 | B39: JydskeVestkysten | C39: JFM | D39: 510 | E39: Haderslev | F39: Syddanmark | G39: daily | H39: paid | I39: regional | J39: 0 | K39: yes | L39: jv.dk | M39: Regionalt dagblad med lokalsektioner; OVERVEJ OM DISSE SKAL TÆLLES MED
A40: NP050 | B40: JydskeVestkysten | C40: JFM | D40: 540 | E40: Sønderborg | F40: Syddanmark | G40: daily | H40: paid | I40: regional | J40: 0 | K40: yes | L40: jv.dk
...

Sheet codebook
A1: Field | B1: Description | C1: Valid Values
A2: newspaper_id | B2: Unique ID per newspaper (NOT per row). One paper covering 3 municipalities = 3 rows, same ID. | C2: NP001, NP002, ...
A3: newspaper_name | B3: Full name of the newspaper | C3: Free text
A4: publisher | B4: Publishing company or owner | C4: Free text (e.g., Jysk Fynske Medier)
A5: kommune_kode | B5: Official municipality code from Danmarks Statistik | C5: 3-digit integer (see municipality_reference sheet)
A6: kommune_name | B6: Municipality name | C6: Must match dk_municipalities.csv
A7: region | B7: Administrative region | C7: Hovedstaden | Sjælland | Syddanmark | Midtjylland | Nordjylland
A8: frequency | B8: Publication frequency | C8: daily | weekly | biweekly | monthly
A9: type | B9: Business model | C9: paid | free | hybrid
A10: distribution | B10: Geographic scope of the paper | C10: local | regional | national
A11: est_circulation | B11: Estimated circulation if known | C11: Integer or blank
A12: has_website | B12: Whether the paper has an active website | C12: yes | no | unknown
... A14: notes | B14: Any additional context | C14: Free text

Sheet municipality_reference
A1: kommune_kode | B1: kommune_name | C1: region | D1: population_approx | E1: newspaper_count | F1: papers_per_10k
A2: 101 | B2: København | C2: Hovedstaden | D2: 652564 | E2: =COUNTIF(newspaper_municipality_map!D:D,A2) -> 0 | F2: =IF(D2>0,E2/D2*10000,"") -> 0
A3: 147 | B3: Frederiksberg | C3: Hovedstaden | D3: 104305 | E3: =COUNTIF(newspaper_municipality_map!D:D,A3) -> 0 | F3: =IF(D3>0,E3/D3*10000,"") -> 0
A4: 151 | B4: Ballerup | C4: Hovedstaden | D4: 49384 | E4: =COUNTIF(newspaper_municipality_map!D:D,A4) -> 0 | F4: =IF(D4>0,E4/D4*10000,"") -> 0
A5: 153 | B5: Brøndby | C5: Hovedstaden | D5: 35698 | E5: =COUNTIF(newspaper_municipality_map!D:D,A5) -> 0 | F5: =IF(D5>0,E5/D5*10000,"") -> 0
A6: 155 | B6: Dragør | C6: Hovedstaden | D6: 14338 | E6: =COUNTIF(newspaper_municipality_map!D:D,A6) -> 0 | F6: =IF(D6>0,E6/D6*10000,"") -> 0
A7: 157 | B7: Gentofte | C7: Hovedstaden | D7: 75753 | E7: =COUNTIF(newspaper_municipality_map!D:D,A7) -> 0 | F7: =IF(D7>0,E7/D7*10000,"") -> 0
A8: 159 | B8: Gladsaxe | C8: Hovedstaden | D8: 70031 | E8: =COUNTIF(newspaper_municipality_map!D:D,A8) -> 0 | F8: =IF(D8>0,E8/D8*10000,"") -> 0
A9: 161 | B9: Glostrup | C9: Hovedstaden | D9: 23382 | E9: =COUNTIF(newspaper_municipality_map!D:D,A9) -> 0 | F9: =IF(D9>0,E9/D9*10000,"") -> 0
A10: 163 | B10: Herlev | C10: Hovedstaden | D10: 28821 | E10: =COUNTIF(newspaper_municipality_map!D:D,A10) -> 0 | F10: =IF(D10>0,E10/D10*10000,"") -> 0
A11: 165 | B11: Albertslund | C11: Hovedstaden | D11: 28072 | E11: =COUNTIF(newspaper_municipality_map!D:D,A11) -> 0 | F11: =IF(D11>0,E11/D11*10000,"") -> 0
A12: 167 | B12: Hvidovre | C12: Hovedstaden | D12: 53835 | E12: =COUNTIF(newspaper_municipality_map!D:D,A12) -> 0 | F12: =IF(D12>0,E12/D12*10000,"") -> 0
A13: 169 | B13: Høje-Taastrup | C13: Hovedstaden | D13: 52773 | E13: =COUNTIF(newspaper_municipality_map!D:D,A13) -> 0 | F13: =IF(D13>0,E13/D13*10000,"") -> 0
... A99: 860 | B99: Hjørring | C99: Nordjylland | D99: 64832 | E99: =COUNTIF(newspaper_municipality_map!D:D,A99) -> 0 | F99: =IF(D99>0,E99/D99*10000,"") -> 0
